<?xml version="1.0" ?>
<robot name="indy" version="1.0">
  <material name="white">
    <color rgba="1.0 1.0 1.0 1.0"/>
  </material>
  <material name="bright_grey">
    <color rgba="0.8 0.8 0.8 1.0"/>
  </material>
  <material name="grey">
    <color rgba="0.5 0.5 0.5 1.0"/>
  </material>
  <material name="transparent_grey">
    <color rgba="0.8 0.8 0.8 0.6"/>
  </material>

  <link name="indy0_link0">
    <inertial>
      <origin rpy="0.0 0.0 0.0" xyz="0.0 0.0 0.0"/>
      <mass value="0.0"/>
      <inertia ixx="0.00572623" ixy="0" ixz="0" iyy="0.00558959" iyz="0" izz="0.00966674"/>
    </inertial>
    <visual>
      <origin rpy="0.0 0.0 0.0" xyz="0.0 0.0 0.00125"/>
      <geometry>
        <mesh filename="/meshes/stl/Indy7_0.stl"/>
      </geometry>
      <material name="bright_grey"/>
    </visual>
    <collision>
      <origin rpy="0.0 0.0 0.0" xyz="-0.1 0.0 0.05"/>
      <geometry>
        <box size="0.14 0.1 0.08"/>
      </geometry>
    </collision>
    <collision>
      <origin rpy="0.0 0.0 0.0" xyz="0.0 0.0 0.05"/>
      <geometry>
        <cylinder length="0.1" radius="0.1"/>
      </geometry>
    </collision>
  </link>

  <link name="indy0_link1">
    <inertial>
      <origin rpy="0.0 0.0 0.0" xyz="0.0 0.0 0.0"/>
      <mass value="11.8030102"/>
      <inertia ixx="0.15418559" ixy="-2.35e-06" ixz="1.739e-05" iyy="0.12937017" iyz="-0.04854267" izz="0.05964415"/>
    </inertial>
    <visual>
      <origin rpy="0.0 0.0 0.0" xyz="0.0 0.0 0.0"/>
      <geometry>
        <mesh filename="/meshes/stl/Indy7_1.stl"/>
      </geometry>
      <material name="white"/>
    </visual>
    <collision>
      <origin rpy="0.0 0.0 0.0" xyz="0.0 0.0 0.1075"/>
      <geometry>
        <cylinder length="0.25" radius="0.08"/>
      </geometry>
    </collision>
  </link>

  <link name="indy0_link2">
    <inertial>
      <origin rpy="0.0 0.0 0.0" xyz="0.0 0.0 0.0"/>
      <mass value="7.99292141"/>
      <inertia ixx="0.2935698" ixy="-4e-07" ixz="1.441e-05" iyy="0.28094142" iyz="0.03727972" izz="0.03620609"/>
    </inertial>
    <visual>
      <origin rpy="0.0 0.0 0.0" xyz="0.0 0.0 0.0"/>
      <geometry>
        <mesh filename="/meshes/stl/IndyRP2_2.stl"/>
      </geometry>
      <material name="white"/>
    </visual>
    <collision>
      <origin rpy="0.0 0.0 0.0" xyz="0.0 0.0 -0.01"/>
      <geometry>
        <cylinder length="0.3" radius="0.085"/>
      </geometry>
    </collision>
  </link>

  <link name="indy0_link3">
    <inertial>
      <origin rpy="0.0 0.0 0.0" xyz="0.0 0.0 0.0"/>
      <mass value="4.08259"/>
      <inertia ixx="0.0132" ixy="0.0" ixz="0.0" iyy="0.0068" iyz="-0.0008" izz="0.0125"/>
    </inertial>
    <visual>
      <origin rpy="0.0 0.0 0.0" xyz="0.0 0.0 0.0"/>
      <geometry>
        <mesh filename="/meshes/stl/IndyRP2_3.stl"/>
      </geometry>
      <material name="white"/>
    </visual>
    <collision>
      <origin rpy="0.0 0.0 0.0" xyz="0.0 0.0 -0.16"/>
      <geometry>
        <cylinder length="0.5" radius="0.073"/>
      </geometry>
    </collision>
  </link>

  <link name="indy0_link4">
    <inertial>
      <origin rpy="0.0 0.0 0.0" xyz="0.0 0.0 0.0"/>
      <mass value="2.99134127"/>
      <inertia ixx="0.03424593" ixy="1.49e-06" ixz="7.24e-06" iyy="0.03406024" iyz="0.00186009" izz="0.00450477"/>
    </inertial>
    <visual>
      <origin rpy="0.0 0.0 0.0" xyz="0.0 0.0 0.0"/>
      <geometry>
        <mesh filename="/meshes/stl/Indy7_3.stl"/>
      </geometry>
      <material name="white"/>
    </visual>
    <collision>
      <origin rpy="0.0 0.0 0.0" xyz="0.0 0.0 0.03"/>
      <geometry>
        <cylinder length="0.25" radius="0.060"/>
      </geometry>
    </collision>
  </link>

  <link name="indy0_link5">
    <inertial>
      <origin rpy="0.0 0.0 0.0" xyz="0.0 0.0 0.0"/>
      <mass value="2.12317035"/>
      <inertia ixx="0.00670405" ixy="3.75e-06" ixz="1.5e-06" iyy="0.00279246" iyz="-0.00127967" izz="0.00619341"/>
    </inertial>
    <visual>
      <origin rpy="0.0 0.0 0.0" xyz="0.0 0.0 0.0"/>
      <geometry>
        <mesh filename="/meshes/stl/Indy7_4.stl"/>
      </geometry>
      <material name="white"/>
    </visual>
    <collision>
      <origin rpy="0.0 0.0 0.0" xyz="0.0 0.0 -0.092"/>
      <geometry>
        <cylinder length="0.4" radius="0.053"/>
      </geometry>
    </collision>
  </link>

  <link name="indy0_link6">
    <inertial>
      <origin rpy="0.0 0.0 0.0" xyz="0.0 0.0 0.0"/>
      <mass value="2.28865091"/>
      <inertia ixx="0.00994891" ixy="1.4e-07" ixz="3.21e-06" iyy="0.00978189" iyz="-0.00093546" izz="0.00271492"/>
    </inertial>
    <visual>
      <origin rpy="0.0 0.0 0.0" xyz="0.0 0.0 0.0"/>
      <geometry>
        <mesh filename="/meshes/stl/Indy7_5.stl"/>
      </geometry>
      <material name="white"/>
    </visual>
    <collision>
      <origin rpy="0.0 0.0 0.0" xyz="-0.0 0.0 -0.0225"/>
      <geometry>
        <cylinder length="0.23" radius="0.05"/>
      </geometry>
    </collision>
  </link>

  <link name="indy0_link7">
    <inertial>
      <origin rpy="0.0 0.0 0.0" xyz="0.0 0.0 0.0"/>
      <mass value="0.40083918"/>
      <inertia ixx="0.00043534" ixy="1.3e-07" ixz="-2e-08" iyy="0.00044549" iyz="5.1e-07" izz="0.00059634"/>
    </inertial>
    <visual>
      <origin rpy="0.0 0.0 0.0" xyz="0.0 0.0 0.0"/>
      <geometry>
        <mesh filename="/meshes/stl/Indy7_6.stl"/>
      </geometry>
      <material name="white"/>
    </visual>
    <collision>
      <origin rpy="0.0 0.0 0.0" xyz="0.0 0.0 -0.058"/>
      <geometry>
        <cylinder length="0.24" radius="0.05"/>
      </geometry>
    </collision>
  </link>

  <joint name="indy0_joint0" type="revolute">
    <origin rpy="0.0 0.0 0.0" xyz="0.0 0.0 0.0775"/>
    <axis xyz="0.0 0.0 1.0"/>
    <parent link="indy0_link0"/>
    <child link="indy0_link1"/>
    <limit effort="78.53981633974483" lower="-2.872" upper="2.872" velocity="2.617993878"/>
  </joint>

  <joint name="indy0_joint1" type="revolute">
    <origin rpy="1.57079632679 1.57079632679 0.0" xyz="0.0 -0.109 0.222"/>
    <axis xyz="0.0 0.0 1.0"/>
    <parent link="indy0_link1"/>
    <child link="indy0_link2"/>
    <limit effort="78.53981633974483" lower="-3.05432619099" upper="3.05432619099" velocity="2.617993878"/>
  </joint>

  <joint name="indy0_joint2" type="revolute">
    <origin rpy="-1.57079632679 0.0 1.57079632679" xyz="-0.3855 0.0 0.0847"/>
    <axis xyz="0.0 0.0 1.0"/>
    <parent link="indy0_link2"/>
    <child link="indy0_link3"/>
    <limit effort="78.53981633974483" lower="-3.05432619099" upper="3.05432619099" velocity="2.617993878"/>
  </joint>

  <joint name="indy0_joint3" type="revolute">
    <origin rpy="1.57079632679 1.57079632679 0.0" xyz="0.0 0.1152 0.0645"/>
    <axis xyz="0.0 0.0 1.0"/>
    <parent link="indy0_link3"/>
    <child link="indy0_link4"/>
    <limit effort="78.53981633974483" lower="-3.05432619099" upper="3.05432619099" velocity="3.141592654"/>
  </joint>

  <joint name="indy0_joint4" type="revolute">
    <origin rpy="-1.57079632679 0.0 1.57079632679" xyz="-0.267 0.0 -0.075"/>
    <axis xyz="0.0 0.0 1.0"/>
    <parent link="indy0_link4"/>
    <child link="indy0_link5"/>
    <limit effort="78.53981633974483" lower="-3.05432619099" upper="3.05432619099" velocity="3.141592654"/>
  </joint>

  <joint name="indy0_joint5" type="revolute">
    <origin rpy="1.57079632679 1.57079632679 0.0" xyz="0.0 -0.114 0.083"/>
    <axis xyz="0.0 0.0 1.0"/>
    <parent link="indy0_link5"/>
    <child link="indy0_link6"/>
    <limit effort="78.53981633974483" lower="-3.05432619099" upper="3.05432619099" velocity="3.141592654"/>
  </joint>

  <joint name="indy0_joint6" type="revolute">
    <origin rpy="-1.57079632679 0.0 1.57079632679" xyz="-0.168 0.0 0.069"/>
    <axis xyz="0.0 0.0 1.0"/>
    <parent link="indy0_link6"/>
    <child link="indy0_link7"/>
    <limit effort="78.53981633974483" lower="-3.05432619099" upper="3.05432619099" velocity="3.141592654"/>
  </joint>

</robot>